<?xml version="1.0" ?>
<!-- =================================================================================== -->
<!-- |    This document was autogenerated by xacro from sr25.xacro                     | -->
<!-- |    EDITING THIS FILE BY HAND IS NOT RECOMMENDED                                 | -->
<!-- =================================================================================== -->
<robot name="sef_roboter" xmlns:xacro="http://ros.org/wiki/xacro">
  <link name="base_link">
    <visual>
      <origin rpy="0 0 0" xyz="0 0 0"/>
      <geometry>
        <mesh filename="package://sef_roboter_support/meshes/sr25/visual/sr25_base_axis.stl"/>
      </geometry>
      <material name="grey">
        <color rgba="0.1 0.1 0.1 1"/>
      </material>
    </visual>
    <collision>
      <origin rpy="0 0 0" xyz="0 0 0"/>
      <geometry>
        <mesh filename="package://sef_roboter_support/meshes/sr25/collision/sr25_base_axis.stl"/>
      </geometry>
      <material name="yellow">
        <color rgba="0 1 1 1"/>
      </material>
    </collision>
  </link>
  <link name="link_1">
    <visual>
      <geometry>
        <mesh filename="package://sef_roboter_support/meshes/sr25/visual/sr25_axis_1.stl"/>
      </geometry>
      <material name="sef_yellow">
        <color rgba="0.8 0.8 0 1"/>
      </material>
    </visual>
    <collision>
      <origin rpy="0 0 0" xyz="0 0 0"/>
      <geometry>
        <mesh filename="package://sef_roboter_support/meshes/sr25/collision/sr25_axis_1.stl"/>
      </geometry>
      <material name="yellow"/>
    </collision>
  </link>
  <link name="link_2">
    <visual>
      <geometry>
        <mesh filename="package://sef_roboter_support/meshes/sr25/visual/sr25_axis_2.stl"/>
      </geometry>
      <material name="sef_yellow"/>
    </visual>
    <collision>
      <geometry>
        <mesh filename="package://sef_roboter_support/meshes/sr25/collision/sr25_axis_2.stl"/>
      </geometry>
      <material name="yellow"/>
    </collision>
  </link>
  <link name="link_3">
    <visual>
      <geometry>
        <mesh filename="package://sef_roboter_support/meshes/sr25/visual/sr25_axis_3.stl"/>
      </geometry>
      <material name="grey"/>
    </visual>
    <collision>
      <geometry>
        <mesh filename="package://sef_roboter_support/meshes/sr25/collision/sr25_axis_3.stl"/>
      </geometry>
      <material name="yellow"/>
    </collision>
  </link>
  <link name="link_4">
    <visual>
      <geometry>
        <mesh filename="package://sef_roboter_support/meshes/sr25/visual/sr25_axis_4.stl"/>
      </geometry>
      <material name="sef_yellow"/>
    </visual>
    <collision>
      <geometry>
        <mesh filename="package://sef_roboter_support/meshes/sr25/collision/sr25_axis_4.stl"/>
      </geometry>
      <material name="yellow"/>
    </collision>
  </link>
  <link name="link_5">
    <visual>
      <geometry>
        <mesh filename="package://sef_roboter_support/meshes/sr25/visual/sr25_axis_5.stl"/>
      </geometry>
      <material name="sef_yellow"/>
    </visual>
    <collision>
      <geometry>
        <mesh filename="package://sef_roboter_support/meshes/sr25/collision/sr25_axis_5.stl"/>
      </geometry>
      <material name="yellow"/>
    </collision>
  </link>
  <link name="link_tool">
    <visual>
      <geometry>
        <mesh filename="package://sef_roboter_support/meshes/sr25/visual/sr25_axis_tool.stl"/>
      </geometry>
      <material name="grey"/>
    </visual>
    <collision>
      <geometry>
        <mesh filename="package://sef_roboter_support/meshes/sr25/collision/sr25_axis_tool.stl"/>
      </geometry>
      <material name="yellow"/>
    </collision>
  </link>
  <joint name="joint_1" type="continuous">
    <parent link="base_link"/>
    <child link="link_1"/>
    <origin rpy="1.5708 0 -1.5745" xyz="0 0 0.075738"/>
    <axis xyz="0 -1 0"/>
    <limit effort="100" lower="-2.8" upper="2.8" velocity="1"/>
  </joint>
  <joint name="joint_2" type="continuous">
    <parent link="link_1"/>
    <child link="link_2"/>
    <origin rpy="1.5687 0 0" xyz="0 0.24264 -0.29599"/>
    <axis xyz="-1 0 0"/>
    <limit effort="100" lower="-0.5" upper="1.5" velocity="1"/>
  </joint>
  <joint name="joint_3" type="continuous">
    <parent link="link_2"/>
    <child link="link_3"/>
    <origin rpy="0.005529 0 0" xyz="0 0 -0.79724"/>
    <axis xyz="-1 0 0"/>
    <limit effort="100" lower="-0.5" upper="1.5" velocity="1"/>
  </joint>
  <joint name="joint_4" type="continuous">
    <parent link="link_3"/>
    <child link="link_4"/>
    <origin rpy="0 0.0014787 0" xyz="0 -0.15811 0"/>
    <axis xyz="0 1 0"/>
    <limit effort="100" lower="-1.6" upper="1.6" velocity="1"/>
  </joint>
  <joint name="joint_5" type="continuous">
    <parent link="link_4"/>
    <child link="link_5"/>
    <origin rpy="0 0 -0.033693" xyz="0 -0.58433 0"/>
    <axis xyz="0 0 1"/>
    <limit effort="100" lower="-3" upper="3" velocity="1"/>
  </joint>
  <joint name="joint_6" type="continuous">
    <parent link="link_5"/>
    <child link="link_tool"/>
    <origin rpy="-1.5707963267949 0.000822590892554664 3.14159265358979" xyz="0 -0.164051291252016 -0.00548103448275694"/>
    <axis xyz="0 0 -1"/>
    <limit effort="100" lower="-2.5" upper="2.5" velocity="1"/>
  </joint>
</robot>

