<?xml version="1.0" ?>
<!-- =================================================================================== -->
<!-- |    This document was autogenerated by xacro from sr25.xacro                     | -->
<!-- |    EDITING THIS FILE BY HAND IS NOT RECOMMENDED                                 | -->
<!-- =================================================================================== -->
<robot name="sef_roboter" xmlns:xacro="http://ros.org/wiki/xacro">
  <!-- Import Rviz colors -->
  <material name="black">
    <color rgba="0.0 0.0 0.0 1.0"/>
  </material>
  <material name="blue">
    <color rgba="0.0 0.0 0.8 1.0"/>
  </material>
  <material name="green">
    <color rgba="0.0 0.8 0.0 1.0"/>
  </material>
  <material name="grey">
    <color rgba="0.2 0.2 0.2 1.0"/>
  </material>
  <material name="orange">
    <color rgba="1.0 0.423529411765 0.0392156862745 1.0"/>
  </material>
  <material name="brown">
    <color rgba="0.870588235294 0.811764705882 0.764705882353 1.0"/>
  </material>
  <material name="red">
    <color rgba="0.8 0.0 0.0 1.0"/>
  </material>
  <material name="white">
    <color rgba="1.0 1.0 1.0 1.0"/>
  </material>
  <material name="yellow">
    <color rgba="1 1 0 1.0"/>
  </material>
  <material name="sef_yellow">
    <color rgba="0.8 0.8 0.0 1.0"/>
  </material>
  <!-- Import Gazebo configuration  -->
  <!-- ros_control plugin -->
  <gazebo>
    <plugin filename="libgazebo_ros_control.so" name="gazebo_ros_control">
      <robotNamespace>/sef_roboter</robotNamespace>
      <robotSimType>gazebo_ros_control/DefaultRobotHWSim</robotSimType>
    </plugin>
  </gazebo>
  <!-- Base Link -->
  <gazebo reference="base_link">
    <material>Gazebo/Grey</material>
  </gazebo>
  <!-- Link1 -->
  <gazebo reference="link_1">
    <material>Gazebo/Grey</material>
  </gazebo>
  <!-- Link2 -->
  <gazebo reference="link_2">
    <material>Gazebo/Yellow</material>
  </gazebo>
  <!-- Link3 -->
  <gazebo reference="link_3">
    <material>Gazebo/Grey</material>
  </gazebo>
  <!-- Link4 -->
  <gazebo reference="link_4">
    <material>Gazebo/Yellow</material>
  </gazebo>
  <!-- Link5 -->
  <gazebo reference="link_5">
    <material>Gazebo/Yellow</material>
  </gazebo>
  <!-- Link6 -->
  <gazebo reference="link_6">
    <material>Gazebo/Grey</material>
  </gazebo>
  <!-- Import Model -->
  <link name="world"/>
  <link name="start_of_service"/>
  <link name="base_link">
    <visual>
      <origin rpy="0 0 0" xyz="0.0 0.0 0.015"/>
      <geometry>
        <mesh filename="package://sef_roboter_support/meshes/sr25/visual/base_link.stl"/>
      </geometry>
      <material name="grey"/>
    </visual>
    <collision>
      <origin rpy="0 0 0" xyz="0.0 -0.001694 0.042616"/>
      <geometry>
        <mesh filename="package://sef_roboter_support/meshes/sr25/collision/base_link.stl"/>
      </geometry>
      <material name="yellow"/>
    </collision>
    <inertial>
      <origin rpy="0 0 0" xyz="0.0 -0.001694 0.042616"/>
      <mass value="100"/>
      <inertia ixx="0.723" ixy="0.0" ixz="0.0" iyy="0.709" iyz="0.003" izz="1.346"/>
    </inertial>
  </link>
  <link name="link_1">
    <visual>
      <geometry>
        <mesh filename="package://sef_roboter_support/meshes/sr25/visual/link_1.stl"/>
      </geometry>
      <material name="grey"/>
    </visual>
    <collision>
      <geometry>
        <mesh filename="package://sef_roboter_support/meshes/sr25/collision/link_1.stl"/>
      </geometry>
      <material name="yellow"/>
    </collision>
    <inertial>
      <origin rpy="0 0 0" xyz="0.034335 0.177684 -0.134564"/>
      <mass value="100"/>
      <inertia ixx="0.681" ixy="-0.024" ixz="0.053" iyy="0.713" iyz="0.160" izz="0.351"/>
    </inertial>
  </link>
  <link name="link_2">
    <visual>
      <geometry>
        <mesh filename="package://sef_roboter_support/meshes/sr25/visual/link_2.stl"/>
      </geometry>
      <material name="sef_yellow"/>
    </visual>
    <collision>
      <geometry>
        <mesh filename="package://sef_roboter_support/meshes/sr25/collision/link_2.stl"/>
      </geometry>
      <material name="yellow"/>
    </collision>
    <inertial>
      <origin rpy="0 0 0" xyz="0.194024 -0.000727 -0.358696"/>
      <mass value="60"/>
      <inertia ixx="2.573" ixy="-0.001" ixz="-0.058" iyy="2.564" iyz="0.007" izz="0.231"/>
    </inertial>
  </link>
  <link name="link_3">
    <visual>
      <geometry>
        <mesh filename="package://sef_roboter_support/meshes/sr25/visual/link_3.stl"/>
      </geometry>
      <material name="grey"/>
    </visual>
    <collision>
      <geometry>
        <mesh filename="package://sef_roboter_support/meshes/sr25/collision/link_3.stl"/>
      </geometry>
      <material name="yellow"/>
    </collision>
    <inertial>
      <origin rpy="0 0 0" xyz="0.002004 0.095949 0.000394"/>
      <mass value="60"/>
      <inertia ixx="0.617" ixy="0.009" ixz="0.001" iyy="0.151" iyz="-0.009" izz="0.571"/>
    </inertial>
  </link>
  <link name="link_4">
    <visual>
      <geometry>
        <mesh filename="package://sef_roboter_support/meshes/sr25/visual/link_4.stl"/>
      </geometry>
      <material name="sef_yellow"/>
    </visual>
    <collision>
      <geometry>
        <mesh filename="package://sef_roboter_support/meshes/sr25/collision/link_4.stl"/>
      </geometry>
      <material name="yellow"/>
    </collision>
    <inertial>
      <origin rpy="0 0 0" xyz="0.000011 -0.329729 -0.000248"/>
      <mass value="40"/>
      <inertia ixx="0.233" ixy="0.0" ixz="0.0" iyy="0.010" iyz="0.0" izz="0.233"/>
    </inertial>
  </link>
  <link name="link_5">
    <visual>
      <geometry>
        <mesh filename="package://sef_roboter_support/meshes/sr25/visual/link_5.stl"/>
      </geometry>
      <material name="sef_yellow"/>
    </visual>
    <collision>
      <geometry>
        <mesh filename="package://sef_roboter_support/meshes/sr25/collision/link_5.stl"/>
      </geometry>
      <material name="yellow"/>
    </collision>
    <inertial>
      <origin rpy="0 0 0" xyz="-0.000029 -0.074224 -0.055689"/>
      <mass value="10"/>
      <inertia ixx="0.015" ixy="0.0" ixz="0.0" iyy="0.009" iyz="0.004" izz="0.011"/>
    </inertial>
  </link>
  <link name="link_6">
    <visual>
      <geometry>
        <mesh filename="package://sef_roboter_support/meshes/sr25/visual/link_6.stl"/>
      </geometry>
      <material name="grey"/>
    </visual>
    <collision>
      <geometry>
        <mesh filename="package://sef_roboter_support/meshes/sr25/collision/link_6.stl"/>
      </geometry>
      <material name="yellow"/>
    </collision>
    <inertial>
      <origin rpy="0 0 0" xyz="0.0 -0.000199 0.017661"/>
      <mass value="5"/>
      <inertia ixx="0.001" ixy="0.0" ixz="0.0" iyy="0.001" iyz="0.0" izz="0.001"/>
    </inertial>
  </link>
  <link name="tool0"/>
  <!-- end of link list -->
  <!-- joint list -->
  <joint name="joint_orig" type="fixed">
    <parent link="world"/>
    <child link="base_link"/>
  </joint>
  <joint name="joint_start_of_service" type="fixed">
    <parent link="world"/>
    <child link="start_of_service"/>
    <origin rpy="0 0 1.5745" xyz="0 0 0"/>
  </joint>
  <joint name="joint_1" type="revolute">
    <parent link="base_link"/>
    <child link="link_1"/>
    <origin rpy="1.5708 0 -1.5745" xyz="0 0 0.075738"/>
    <axis xyz="0 -1 0"/>
    <limit effort="10000" lower="-1.57" upper="1.57" velocity="1"/>
    <dynamics damping="0.7" friction="100"/>
  </joint>
  <joint name="joint_2" type="revolute">
    <parent link="link_1"/>
    <child link="link_2"/>
    <origin rpy="1.5687 0 0" xyz="0 0.24264 -0.29599"/>
    <axis xyz="-1 0 0"/>
    <limit effort="10000" lower="-0.5" upper="1.5" velocity="1"/>
    <dynamics damping="0.7" friction="100"/>
  </joint>
  <joint name="joint_3" type="revolute">
    <parent link="link_2"/>
    <child link="link_3"/>
    <origin rpy="0.005529 0 0" xyz="0 0 -0.79724"/>
    <axis xyz="-1 0 0"/>
    <limit effort="10000" lower="-1.5" upper="0.5" velocity="1"/>
    <dynamics damping="0.7" friction="100"/>
  </joint>
  <joint name="joint_4" type="revolute">
    <parent link="link_3"/>
    <child link="link_4"/>
    <origin rpy="0 0.0014787 0" xyz="0 -0.15811 0"/>
    <axis xyz="0 1 0"/>
    <limit effort="10000" lower="-1.57" upper="1.57" velocity="1"/>
    <dynamics damping="0.7" friction="100"/>
  </joint>
  <joint name="joint_5" type="revolute">
    <parent link="link_4"/>
    <child link="link_5"/>
    <origin rpy="0 0 -0.033693" xyz="0 -0.58433 0"/>
    <axis xyz="0 0 1"/>
    <limit effort="10000" lower="-1.6" upper="1.6" velocity="1"/>
    <dynamics damping="0.7" friction="100"/>
  </joint>
  <joint name="joint_6" type="revolute">
    <parent link="link_5"/>
    <child link="link_6"/>
    <origin rpy="-1.5707 0 3.1415" xyz="0 -0.16405 -0.00548"/>
    <axis xyz="0 0 -1 "/>
    <limit effort="100" lower="-2.5" upper="2.5" velocity="1"/>
    <dynamics damping="0.7" friction="100"/>
  </joint>
  <joint name="joint_6-tool0" type="fixed">
    <parent link="link_6"/>
    <child link="tool0"/>
    <origin rpy="0 0 -1.57" xyz="0 0 0"/>
  </joint>
  <!-- end of joint list -->
  <transmission name="tran_1">
    <type>transmission_interface/SimpleTransmission</type>
    <joint name="joint_1">
      <hardwareInterface>VelocityJointInterface</hardwareInterface>
    </joint>
    <actuator name="motor_1">
      <hardwareInterface>VelocityJointInterface</hardwareInterface>
      <mechanicalReduction>80</mechanicalReduction>
    </actuator>
  </transmission>
  <transmission name="tran_2">
    <type>transmission_interface/SimpleTransmission</type>
    <joint name="joint_2">
      <hardwareInterface>VelocityJointInterface</hardwareInterface>
    </joint>
    <actuator name="motor_2">
      <hardwareInterface>VelocityJointInterface</hardwareInterface>
      <mechanicalReduction>120</mechanicalReduction>
    </actuator>
  </transmission>
  <transmission name="tran_3">
    <type>transmission_interface/SimpleTransmission</type>
    <joint name="joint_3">
      <hardwareInterface>VelocityJointInterface</hardwareInterface>
    </joint>
    <actuator name="motor_3">
      <hardwareInterface>VelocityJointInterface</hardwareInterface>
      <mechanicalReduction>108</mechanicalReduction>
    </actuator>
  </transmission>
  <transmission name="tran_4">
    <type>transmission_interface/SimpleTransmission</type>
    <joint name="joint_4">
      <hardwareInterface>VelocityJointInterface</hardwareInterface>
    </joint>
    <actuator name="motor_4">
      <hardwareInterface>VelocityJointInterface</hardwareInterface>
      <mechanicalReduction>76.5</mechanicalReduction>
    </actuator>
  </transmission>
  <transmission name="tran_5">
    <type>transmission_interface/SimpleTransmission</type>
    <joint name="joint_5">
      <hardwareInterface>VelocityJointInterface</hardwareInterface>
    </joint>
    <actuator name="motor_5">
      <hardwareInterface>VelocityJointInterface</hardwareInterface>
      <mechanicalReduction>100.5</mechanicalReduction>
    </actuator>
  </transmission>
  <transmission name="tran_6">
    <type>transmission_interface/SimpleTransmission</type>
    <joint name="joint_6">
      <hardwareInterface>VelocityJointInterface</hardwareInterface>
    </joint>
    <actuator name="motor_6">
      <hardwareInterface>VelocityJointInterface</hardwareInterface>
      <mechanicalReduction>92.2</mechanicalReduction>
    </actuator>
  </transmission>
</robot>

